<robot name="OpenLoog" version="1.0">
  <link name="base_link">
    <inertial>
      <origin xyz="-0.0056641 -0.0013367 0.23829" rpy="0.0 0.0 0.0"/>
      <mass value="22.447"/>
      <inertia ixx="0.3742" ixy="0.0009471" ixz="0.004646" iyy="0.27691" iyz="0.0040142" izz="0.22104"/>
    </inertial>
    <visual>
      <origin xyz="0.0 0.0 0.0" rpy="0.0 0.0 0.0"/>
      <geometry>
        <mesh filename="package://openloong_description/meshes/base_link.stl"/>
      </geometry>
      <material name="">
        <color rgba="0.75294 0.75294 0.75294 1.0"/>
      </material>
    </visual>
    <collision><origin xyz="0.0 0.0 0.0" rpy="0.0 0.0 0.0"/><geometry><mesh filename="file:///home/tim/github/ROS/robot_decompose/openloong_description/meshes/base_link.stl_0.stl"/></geometry></collision><collision><origin xyz="0.0 0.0 0.0" rpy="0.0 0.0 0.0"/><geometry><mesh filename="file:///home/tim/github/ROS/robot_decompose/openloong_description/meshes/base_link.stl_1.stl"/></geometry></collision><collision><origin xyz="0.0 0.0 0.0" rpy="0.0 0.0 0.0"/><geometry><mesh filename="file:///home/tim/github/ROS/robot_decompose/openloong_description/meshes/base_link.stl_2.stl"/></geometry></collision><collision><origin xyz="0.0 0.0 0.0" rpy="0.0 0.0 0.0"/><geometry><mesh filename="file:///home/tim/github/ROS/robot_decompose/openloong_description/meshes/base_link.stl_3.stl"/></geometry></collision></link>
  <link name="Link_head_yaw">
    <inertial>
      <origin xyz="4.6974e-12 -0.0020814 0.044801" rpy="0.0 0.0 0.0"/>
      <mass value="0.84249"/>
      <inertia ixx="0.000629" ixy="1.2848e-14" ixz="-1.5461e-10" iyy="0.0007003" iyz="-6.5e-06" izz="0.0005541"/>
    </inertial>
    <visual>
      <origin xyz="0.0 0.0 0.0" rpy="0.0 0.0 0.0"/>
      <geometry>
        <mesh filename="package://openloong_description/meshes/Link_head_yaw.stl"/>
      </geometry>
      <material name="">
        <color rgba="0.89804 0.91765 0.92941 1.0"/>
      </material>
    </visual>
    <collision><origin xyz="0.0 0.0 0.0" rpy="0.0 0.0 0.0"/><geometry><mesh filename="file:///home/tim/github/ROS/robot_decompose/openloong_description/meshes/Link_head_yaw.stl_0.stl"/></geometry></collision><collision><origin xyz="0.0 0.0 0.0" rpy="0.0 0.0 0.0"/><geometry><mesh filename="file:///home/tim/github/ROS/robot_decompose/openloong_description/meshes/Link_head_yaw.stl_1.stl"/></geometry></collision><collision><origin xyz="0.0 0.0 0.0" rpy="0.0 0.0 0.0"/><geometry><mesh filename="file:///home/tim/github/ROS/robot_decompose/openloong_description/meshes/Link_head_yaw.stl_2.stl"/></geometry></collision><collision><origin xyz="0.0 0.0 0.0" rpy="0.0 0.0 0.0"/><geometry><mesh filename="file:///home/tim/github/ROS/robot_decompose/openloong_description/meshes/Link_head_yaw.stl_3.stl"/></geometry></collision><collision><origin xyz="0.0 0.0 0.0" rpy="0.0 0.0 0.0"/><geometry><mesh filename="file:///home/tim/github/ROS/robot_decompose/openloong_description/meshes/Link_head_yaw.stl_4.stl"/></geometry></collision><collision><origin xyz="0.0 0.0 0.0" rpy="0.0 0.0 0.0"/><geometry><mesh filename="file:///home/tim/github/ROS/robot_decompose/openloong_description/meshes/Link_head_yaw.stl_5.stl"/></geometry></collision><collision><origin xyz="0.0 0.0 0.0" rpy="0.0 0.0 0.0"/><geometry><mesh filename="file:///home/tim/github/ROS/robot_decompose/openloong_description/meshes/Link_head_yaw.stl_6.stl"/></geometry></collision><collision><origin xyz="0.0 0.0 0.0" rpy="0.0 0.0 0.0"/><geometry><mesh filename="file:///home/tim/github/ROS/robot_decompose/openloong_description/meshes/Link_head_yaw.stl_7.stl"/></geometry></collision><collision><origin xyz="0.0 0.0 0.0" rpy="0.0 0.0 0.0"/><geometry><mesh filename="file:///home/tim/github/ROS/robot_decompose/openloong_description/meshes/Link_head_yaw.stl_8.stl"/></geometry></collision></link>
  <joint name="J_head_yaw" type="revolute">
    <origin xyz="0.009 0.0 0.4064" rpy="0.0 0.0 0.0"/>
    <axis xyz="0.0 0.0 1.0"/>
    <parent link="base_link"/>
    <child link="Link_head_yaw"/>
    <limit effort="26.0" lower="-1.5708" upper="1.5708" velocity="109.8"/>
  </joint>
  <link name="Link_head_pitch">
    <inertial>
      <origin xyz="0.020569 0.033004 0.125" rpy="0.0 0.0 0.0"/>
      <mass value="1.3943"/>
      <inertia ixx="0.0060059" ixy="9.4e-06" ixz="-0.0007564" iyy="0.00629" iyz="1.03e-05" izz="0.0048569"/>
    </inertial>
    <visual>
      <origin xyz="0.0 0.0 0.0" rpy="0.0 0.0 0.0"/>
      <geometry>
        <mesh filename="package://openloong_description/meshes/Link_head_pitch.stl"/>
      </geometry>
      <material name="">
        <color rgba="0.69804 0.69804 0.69804 1.0"/>
      </material>
    </visual>
    <collision><origin xyz="0.0 0.0 0.0" rpy="0.0 0.0 0.0"/><geometry><mesh filename="file:///home/tim/github/ROS/robot_decompose/openloong_description/meshes/Link_head_pitch.stl_0.stl"/></geometry></collision><collision><origin xyz="0.0 0.0 0.0" rpy="0.0 0.0 0.0"/><geometry><mesh filename="file:///home/tim/github/ROS/robot_decompose/openloong_description/meshes/Link_head_pitch.stl_1.stl"/></geometry></collision><collision><origin xyz="0.0 0.0 0.0" rpy="0.0 0.0 0.0"/><geometry><mesh filename="file:///home/tim/github/ROS/robot_decompose/openloong_description/meshes/Link_head_pitch.stl_2.stl"/></geometry></collision><collision><origin xyz="0.0 0.0 0.0" rpy="0.0 0.0 0.0"/><geometry><mesh filename="file:///home/tim/github/ROS/robot_decompose/openloong_description/meshes/Link_head_pitch.stl_3.stl"/></geometry></collision><collision><origin xyz="0.0 0.0 0.0" rpy="0.0 0.0 0.0"/><geometry><mesh filename="file:///home/tim/github/ROS/robot_decompose/openloong_description/meshes/Link_head_pitch.stl_4.stl"/></geometry></collision><collision><origin xyz="0.0 0.0 0.0" rpy="0.0 0.0 0.0"/><geometry><mesh filename="file:///home/tim/github/ROS/robot_decompose/openloong_description/meshes/Link_head_pitch.stl_5.stl"/></geometry></collision><collision><origin xyz="0.0 0.0 0.0" rpy="0.0 0.0 0.0"/><geometry><mesh filename="file:///home/tim/github/ROS/robot_decompose/openloong_description/meshes/Link_head_pitch.stl_6.stl"/></geometry></collision><collision><origin xyz="0.0 0.0 0.0" rpy="0.0 0.0 0.0"/><geometry><mesh filename="file:///home/tim/github/ROS/robot_decompose/openloong_description/meshes/Link_head_pitch.stl_7.stl"/></geometry></collision><collision><origin xyz="0.0 0.0 0.0" rpy="0.0 0.0 0.0"/><geometry><mesh filename="file:///home/tim/github/ROS/robot_decompose/openloong_description/meshes/Link_head_pitch.stl_8.stl"/></geometry></collision><collision><origin xyz="0.0 0.0 0.0" rpy="0.0 0.0 0.0"/><geometry><mesh filename="file:///home/tim/github/ROS/robot_decompose/openloong_description/meshes/Link_head_pitch.stl_9.stl"/></geometry></collision><collision><origin xyz="0.0 0.0 0.0" rpy="0.0 0.0 0.0"/><geometry><mesh filename="file:///home/tim/github/ROS/robot_decompose/openloong_description/meshes/Link_head_pitch.stl_10.stl"/></geometry></collision><collision><origin xyz="0.0 0.0 0.0" rpy="0.0 0.0 0.0"/><geometry><mesh filename="file:///home/tim/github/ROS/robot_decompose/openloong_description/meshes/Link_head_pitch.stl_11.stl"/></geometry></collision><collision><origin xyz="0.0 0.0 0.0" rpy="0.0 0.0 0.0"/><geometry><mesh filename="file:///home/tim/github/ROS/robot_decompose/openloong_description/meshes/Link_head_pitch.stl_12.stl"/></geometry></collision><collision><origin xyz="0.0 0.0 0.0" rpy="0.0 0.0 0.0"/><geometry><mesh filename="file:///home/tim/github/ROS/robot_decompose/openloong_description/meshes/Link_head_pitch.stl_13.stl"/></geometry></collision><collision><origin xyz="0.0 0.0 0.0" rpy="0.0 0.0 0.0"/><geometry><mesh filename="file:///home/tim/github/ROS/robot_decompose/openloong_description/meshes/Link_head_pitch.stl_14.stl"/></geometry></collision><collision><origin xyz="0.0 0.0 0.0" rpy="0.0 0.0 0.0"/><geometry><mesh filename="file:///home/tim/github/ROS/robot_decompose/openloong_description/meshes/Link_head_pitch.stl_15.stl"/></geometry></collision></link>
  <joint name="J_head_pitch" type="revolute">
    <origin xyz="0.0 -0.0345999999999997 0.0484999999999999" rpy="0.0 0.0 0.0"/>
    <axis xyz="0.0 -1.0 0.0"/>
    <parent link="Link_head_yaw"/>
    <child link="Link_head_pitch"/>
    <limit effort="26.0" lower="-0.7854" upper="0.7854" velocity="109.8"/>
  </joint>
  <link name="Link_arm_r_01">
    <inertial>
      <origin xyz="0.0044946 -0.038294 -1.8744e-06" rpy="0.0 0.0 0.0"/>
      <mass value="0.75641"/>
      <inertia ixx="0.00058712" ixy="-2.9803e-07" ixz="-5.8378e-09" iyy="0.00080305" iyz="3.6648e-08" izz="0.00084299"/>
    </inertial>
    <visual>
      <origin xyz="0.0 0.0 0.0" rpy="0.0 0.0 0.0"/>
      <geometry>
        <mesh filename="package://openloong_description/meshes/Link_arm_r_01.stl"/>
      </geometry>
      <material name="">
        <color rgba="0.69804 0.69804 0.69804 1.0"/>
      </material>
    </visual>
    <collision><origin xyz="0.0 0.0 0.0" rpy="0.0 0.0 0.0"/><geometry><mesh filename="file:///home/tim/github/ROS/robot_decompose/openloong_description/meshes/Link_arm_r_01.stl_0.stl"/></geometry></collision><collision><origin xyz="0.0 0.0 0.0" rpy="0.0 0.0 0.0"/><geometry><mesh filename="file:///home/tim/github/ROS/robot_decompose/openloong_description/meshes/Link_arm_r_01.stl_1.stl"/></geometry></collision><collision><origin xyz="0.0 0.0 0.0" rpy="0.0 0.0 0.0"/><geometry><mesh filename="file:///home/tim/github/ROS/robot_decompose/openloong_description/meshes/Link_arm_r_01.stl_2.stl"/></geometry></collision><collision><origin xyz="0.0 0.0 0.0" rpy="0.0 0.0 0.0"/><geometry><mesh filename="file:///home/tim/github/ROS/robot_decompose/openloong_description/meshes/Link_arm_r_01.stl_3.stl"/></geometry></collision><collision><origin xyz="0.0 0.0 0.0" rpy="0.0 0.0 0.0"/><geometry><mesh filename="file:///home/tim/github/ROS/robot_decompose/openloong_description/meshes/Link_arm_r_01.stl_4.stl"/></geometry></collision><collision><origin xyz="0.0 0.0 0.0" rpy="0.0 0.0 0.0"/><geometry><mesh filename="file:///home/tim/github/ROS/robot_decompose/openloong_description/meshes/Link_arm_r_01.stl_5.stl"/></geometry></collision><collision><origin xyz="0.0 0.0 0.0" rpy="0.0 0.0 0.0"/><geometry><mesh filename="file:///home/tim/github/ROS/robot_decompose/openloong_description/meshes/Link_arm_r_01.stl_6.stl"/></geometry></collision><collision><origin xyz="0.0 0.0 0.0" rpy="0.0 0.0 0.0"/><geometry><mesh filename="file:///home/tim/github/ROS/robot_decompose/openloong_description/meshes/Link_arm_r_01.stl_7.stl"/></geometry></collision><collision><origin xyz="0.0 0.0 0.0" rpy="0.0 0.0 0.0"/><geometry><mesh filename="file:///home/tim/github/ROS/robot_decompose/openloong_description/meshes/Link_arm_r_01.stl_8.stl"/></geometry></collision><collision><origin xyz="0.0 0.0 0.0" rpy="0.0 0.0 0.0"/><geometry><mesh filename="file:///home/tim/github/ROS/robot_decompose/openloong_description/meshes/Link_arm_r_01.stl_9.stl"/></geometry></collision><collision><origin xyz="0.0 0.0 0.0" rpy="0.0 0.0 0.0"/><geometry><mesh filename="file:///home/tim/github/ROS/robot_decompose/openloong_description/meshes/Link_arm_r_01.stl_10.stl"/></geometry></collision><collision><origin xyz="0.0 0.0 0.0" rpy="0.0 0.0 0.0"/><geometry><mesh filename="file:///home/tim/github/ROS/robot_decompose/openloong_description/meshes/Link_arm_r_01.stl_11.stl"/></geometry></collision><collision><origin xyz="0.0 0.0 0.0" rpy="0.0 0.0 0.0"/><geometry><mesh filename="file:///home/tim/github/ROS/robot_decompose/openloong_description/meshes/Link_arm_r_01.stl_12.stl"/></geometry></collision><collision><origin xyz="0.0 0.0 0.0" rpy="0.0 0.0 0.0"/><geometry><mesh filename="file:///home/tim/github/ROS/robot_decompose/openloong_description/meshes/Link_arm_r_01.stl_13.stl"/></geometry></collision><collision><origin xyz="0.0 0.0 0.0" rpy="0.0 0.0 0.0"/><geometry><mesh filename="file:///home/tim/github/ROS/robot_decompose/openloong_description/meshes/Link_arm_r_01.stl_14.stl"/></geometry></collision><collision><origin xyz="0.0 0.0 0.0" rpy="0.0 0.0 0.0"/><geometry><mesh filename="file:///home/tim/github/ROS/robot_decompose/openloong_description/meshes/Link_arm_r_01.stl_15.stl"/></geometry></collision><collision><origin xyz="0.0 0.0 0.0" rpy="0.0 0.0 0.0"/><geometry><mesh filename="file:///home/tim/github/ROS/robot_decompose/openloong_description/meshes/Link_arm_r_01.stl_16.stl"/></geometry></collision><collision><origin xyz="0.0 0.0 0.0" rpy="0.0 0.0 0.0"/><geometry><mesh filename="file:///home/tim/github/ROS/robot_decompose/openloong_description/meshes/Link_arm_r_01.stl_17.stl"/></geometry></collision><collision><origin xyz="0.0 0.0 0.0" rpy="0.0 0.0 0.0"/><geometry><mesh filename="file:///home/tim/github/ROS/robot_decompose/openloong_description/meshes/Link_arm_r_01.stl_18.stl"/></geometry></collision><collision><origin xyz="0.0 0.0 0.0" rpy="0.0 0.0 0.0"/><geometry><mesh filename="file:///home/tim/github/ROS/robot_decompose/openloong_description/meshes/Link_arm_r_01.stl_19.stl"/></geometry></collision><collision><origin xyz="0.0 0.0 0.0" rpy="0.0 0.0 0.0"/><geometry><mesh filename="file:///home/tim/github/ROS/robot_decompose/openloong_description/meshes/Link_arm_r_01.stl_20.stl"/></geometry></collision><collision><origin xyz="0.0 0.0 0.0" rpy="0.0 0.0 0.0"/><geometry><mesh filename="file:///home/tim/github/ROS/robot_decompose/openloong_description/meshes/Link_arm_r_01.stl_21.stl"/></geometry></collision><collision><origin xyz="0.0 0.0 0.0" rpy="0.0 0.0 0.0"/><geometry><mesh filename="file:///home/tim/github/ROS/robot_decompose/openloong_description/meshes/Link_arm_r_01.stl_22.stl"/></geometry></collision><collision><origin xyz="0.0 0.0 0.0" rpy="0.0 0.0 0.0"/><geometry><mesh filename="file:///home/tim/github/ROS/robot_decompose/openloong_description/meshes/Link_arm_r_01.stl_23.stl"/></geometry></collision><collision><origin xyz="0.0 0.0 0.0" rpy="0.0 0.0 0.0"/><geometry><mesh filename="file:///home/tim/github/ROS/robot_decompose/openloong_description/meshes/Link_arm_r_01.stl_24.stl"/></geometry></collision><collision><origin xyz="0.0 0.0 0.0" rpy="0.0 0.0 0.0"/><geometry><mesh filename="file:///home/tim/github/ROS/robot_decompose/openloong_description/meshes/Link_arm_r_01.stl_25.stl"/></geometry></collision><collision><origin xyz="0.0 0.0 0.0" rpy="0.0 0.0 0.0"/><geometry><mesh filename="file:///home/tim/github/ROS/robot_decompose/openloong_description/meshes/Link_arm_r_01.stl_26.stl"/></geometry></collision><collision><origin xyz="0.0 0.0 0.0" rpy="0.0 0.0 0.0"/><geometry><mesh filename="file:///home/tim/github/ROS/robot_decompose/openloong_description/meshes/Link_arm_r_01.stl_27.stl"/></geometry></collision><collision><origin xyz="0.0 0.0 0.0" rpy="0.0 0.0 0.0"/><geometry><mesh filename="file:///home/tim/github/ROS/robot_decompose/openloong_description/meshes/Link_arm_r_01.stl_28.stl"/></geometry></collision></link>
  <joint name="J_arm_r_01" type="revolute">
    <origin xyz="0.004 -0.1616 0.3922" rpy="0.0 0.0 0.0"/>
    <axis xyz="0.0 -1.0 0.0"/>
    <parent link="base_link"/>
    <child link="Link_arm_r_01"/>
    <limit effort="80.0" lower="-2.96706" upper="2.96706" velocity="3.14"/>
  </joint>
  <link name="Link_arm_r_02">
    <inertial>
      <origin xyz="0.042 -0.0674307499121858 -6.93889390390723e-18" rpy="0.0 0.0 0.0"/>
      <mass value="0.984999996273518"/>
      <inertia ixx="0.0017309882399251" ixy="9.79515256436727e-20" ixz="3.63988309726277e-19" iyy="0.00115401958000568" iyz="-4.42134220053852e-19" izz="0.00226269324370836"/>
    </inertial>
    <visual>
      <origin xyz="0.0 0.0 0.0" rpy="0.0 0.0 0.0"/>
      <geometry>
        <mesh filename="package://openloong_description/meshes/Link_arm_r_02.stl"/>
      </geometry>
      <material name="">
        <color rgba="0.698039215686274 0.698039215686274 0.698039215686274 1.0"/>
      </material>
    </visual>
    <collision><origin xyz="0.0 0.0 0.0" rpy="0.0 0.0 0.0"/><geometry><mesh filename="file:///home/tim/github/ROS/robot_decompose/openloong_description/meshes/Link_arm_r_02.stl_0.stl"/></geometry></collision><collision><origin xyz="0.0 0.0 0.0" rpy="0.0 0.0 0.0"/><geometry><mesh filename="file:///home/tim/github/ROS/robot_decompose/openloong_description/meshes/Link_arm_r_02.stl_1.stl"/></geometry></collision><collision><origin xyz="0.0 0.0 0.0" rpy="0.0 0.0 0.0"/><geometry><mesh filename="file:///home/tim/github/ROS/robot_decompose/openloong_description/meshes/Link_arm_r_02.stl_2.stl"/></geometry></collision><collision><origin xyz="0.0 0.0 0.0" rpy="0.0 0.0 0.0"/><geometry><mesh filename="file:///home/tim/github/ROS/robot_decompose/openloong_description/meshes/Link_arm_r_02.stl_3.stl"/></geometry></collision><collision><origin xyz="0.0 0.0 0.0" rpy="0.0 0.0 0.0"/><geometry><mesh filename="file:///home/tim/github/ROS/robot_decompose/openloong_description/meshes/Link_arm_r_02.stl_4.stl"/></geometry></collision></link>
  <joint name="J_arm_r_02" type="revolute">
    <origin xyz="-0.042 -0.041 0.0" rpy="0.0 0.0 0.0"/>
    <axis xyz="-1.0 0.0 0.0"/>
    <parent link="Link_arm_r_01"/>
    <child link="Link_arm_r_02"/>
    <limit effort="80.0" lower="-1.8326" upper="1.8326" velocity="3.14"/>
  </joint>
  <link name="Link_arm_r_03">
    <inertial>
      <origin xyz="-0.00141357502419955 -0.164662742175383 0.0207578924800774" rpy="0.0 0.0 0.0"/>
      <mass value="0.958999855228924"/>
      <inertia ixx="0.00206438134078715" ixy="-1.82014067823509e-05" ixz="5.1283136963991e-06" iyy="0.00080535412926664" iyz="0.000255265992194607" izz="0.00205099914609259"/>
    </inertial>
    <visual>
      <origin xyz="0.0 0.0 0.0" rpy="0.0 0.0 0.0"/>
      <geometry>
        <mesh filename="package://openloong_description/meshes/Link_arm_r_03.stl"/>
      </geometry>
      <material name="">
        <color rgba="0.698039215686274 0.698039215686274 0.698039215686274 1.0"/>
      </material>
    </visual>
    <collision><origin xyz="0.0 0.0 0.0" rpy="0.0 0.0 0.0"/><geometry><mesh filename="file:///home/tim/github/ROS/robot_decompose/openloong_description/meshes/Link_arm_r_03.stl_0.stl"/></geometry></collision><collision><origin xyz="0.0 0.0 0.0" rpy="0.0 0.0 0.0"/><geometry><mesh filename="file:///home/tim/github/ROS/robot_decompose/openloong_description/meshes/Link_arm_r_03.stl_1.stl"/></geometry></collision></link>
  <joint name="J_arm_r_03" type="revolute">
    <origin xyz="0.042 -0.1226 0.0" rpy="0.0 0.0 0.0"/>
    <axis xyz="0.0 -1.0 0.0"/>
    <parent link="Link_arm_r_02"/>
    <child link="Link_arm_r_03"/>
    <limit effort="48.0" lower="-2.96706" upper="2.96706" velocity="3.14"/>
  </joint>
  <link name="Link_arm_r_04">
    <inertial>
      <origin xyz="-0.038727 -0.060767 -0.021003" rpy="0.0 0.0 0.0"/>
      <mass value="0.6"/>
      <inertia ixx="0.00070398" ixy="2.023e-05" ixz="1.1263e-05" iyy="0.00068085" iyz="-0.00010585" izz="0.0010653"/>
    </inertial>
    <visual>
      <origin xyz="0.0 0.0 0.0" rpy="0.0 0.0 0.0"/>
      <geometry>
        <mesh filename="package://openloong_description/meshes/Link_arm_r_04.stl"/>
      </geometry>
      <material name="">
        <color rgba="0.69804 0.69804 0.69804 1.0"/>
      </material>
    </visual>
    <collision><origin xyz="0.0 0.0 0.0" rpy="0.0 0.0 0.0"/><geometry><mesh filename="file:///home/tim/github/ROS/robot_decompose/openloong_description/meshes/Link_arm_r_04.stl_0.stl"/></geometry></collision><collision><origin xyz="0.0 0.0 0.0" rpy="0.0 0.0 0.0"/><geometry><mesh filename="file:///home/tim/github/ROS/robot_decompose/openloong_description/meshes/Link_arm_r_04.stl_1.stl"/></geometry></collision><collision><origin xyz="0.0 0.0 0.0" rpy="0.0 0.0 0.0"/><geometry><mesh filename="file:///home/tim/github/ROS/robot_decompose/openloong_description/meshes/Link_arm_r_04.stl_2.stl"/></geometry></collision><collision><origin xyz="0.0 0.0 0.0" rpy="0.0 0.0 0.0"/><geometry><mesh filename="file:///home/tim/github/ROS/robot_decompose/openloong_description/meshes/Link_arm_r_04.stl_3.stl"/></geometry></collision><collision><origin xyz="0.0 0.0 0.0" rpy="0.0 0.0 0.0"/><geometry><mesh filename="file:///home/tim/github/ROS/robot_decompose/openloong_description/meshes/Link_arm_r_04.stl_4.stl"/></geometry></collision><collision><origin xyz="0.0 0.0 0.0" rpy="0.0 0.0 0.0"/><geometry><mesh filename="file:///home/tim/github/ROS/robot_decompose/openloong_description/meshes/Link_arm_r_04.stl_5.stl"/></geometry></collision></link>
  <joint name="J_arm_r_04" type="revolute">
    <origin xyz="0.0353 -0.1774 0.024" rpy="0.0 0.0 0.0"/>
    <axis xyz="-1.0 0.0 0.0"/>
    <parent link="Link_arm_r_03"/>
    <child link="Link_arm_r_04"/>
    <limit effort="48.0" lower="0.0" upper="2.96706" velocity="3.14"/>
  </joint>
  <link name="Link_arm_r_05">
    <inertial>
      <origin xyz="3.2712e-05 -0.068658 -0.00011178" rpy="0.0 0.0 0.0"/>
      <mass value="0.68976"/>
      <inertia ixx="0.0025225" ixy="-4e-07" ixz="8e-07" iyy="0.0004487" iyz="3.1e-06" izz="0.0024111"/>
    </inertial>
    <visual>
      <origin xyz="0.0 0.0 0.0" rpy="0.0 0.0 0.0"/>
      <geometry>
        <mesh filename="package://openloong_description/meshes/Link_arm_r_05.stl"/>
      </geometry>
      <material name="">
        <color rgba="0.69804 0.69804 0.69804 1.0"/>
      </material>
    </visual>
    <collision><origin xyz="0.0 0.0 0.0" rpy="0.0 0.0 0.0"/><geometry><mesh filename="file:///home/tim/github/ROS/robot_decompose/openloong_description/meshes/Link_arm_r_05.stl_0.stl"/></geometry></collision><collision><origin xyz="0.0 0.0 0.0" rpy="0.0 0.0 0.0"/><geometry><mesh filename="file:///home/tim/github/ROS/robot_decompose/openloong_description/meshes/Link_arm_r_05.stl_1.stl"/></geometry></collision><collision><origin xyz="0.0 0.0 0.0" rpy="0.0 0.0 0.0"/><geometry><mesh filename="file:///home/tim/github/ROS/robot_decompose/openloong_description/meshes/Link_arm_r_05.stl_2.stl"/></geometry></collision><collision><origin xyz="0.0 0.0 0.0" rpy="0.0 0.0 0.0"/><geometry><mesh filename="file:///home/tim/github/ROS/robot_decompose/openloong_description/meshes/Link_arm_r_05.stl_3.stl"/></geometry></collision><collision><origin xyz="0.0 0.0 0.0" rpy="0.0 0.0 0.0"/><geometry><mesh filename="file:///home/tim/github/ROS/robot_decompose/openloong_description/meshes/Link_arm_r_05.stl_4.stl"/></geometry></collision><collision><origin xyz="0.0 0.0 0.0" rpy="0.0 0.0 0.0"/><geometry><mesh filename="file:///home/tim/github/ROS/robot_decompose/openloong_description/meshes/Link_arm_r_05.stl_5.stl"/></geometry></collision><collision><origin xyz="0.0 0.0 0.0" rpy="0.0 0.0 0.0"/><geometry><mesh filename="file:///home/tim/github/ROS/robot_decompose/openloong_description/meshes/Link_arm_r_05.stl_6.stl"/></geometry></collision></link>
  <joint name="J_arm_r_05" type="revolute">
    <origin xyz="-0.0353 -0.1035 -0.024" rpy="0.0 0.0 0.0"/>
    <axis xyz="0.0 -1.0 0.0"/>
    <parent link="Link_arm_r_04"/>
    <child link="Link_arm_r_05"/>
    <limit effort="12.4" lower="-2.96706" upper="2.96706" velocity="6.28"/>
  </joint>
  <link name="Link_arm_r_06">
    <inertial>
      <origin xyz="0.026078 -8.9588e-07 0.0016637" rpy="0.0 0.0 0.0"/>
      <mass value="0.28"/>
      <inertia ixx="0.0001456" ixy="-7.7026e-10" ixz="-2.1456e-07" iyy="0.00015693" iyz="-2.4102e-09" izz="0.00010498"/>
    </inertial>
    <visual>
      <origin xyz="0.0 0.0 0.0" rpy="0.0 0.0 0.0"/>
      <geometry>
        <mesh filename="package://openloong_description/meshes/Link_arm_r_06.stl"/>
      </geometry>
      <material name="">
        <color rgba="0.69804 0.69804 0.69804 1.0"/>
      </material>
    </visual>
    <collision><origin xyz="0.0 0.0 0.0" rpy="0.0 0.0 0.0"/><geometry><mesh filename="file:///home/tim/github/ROS/robot_decompose/openloong_description/meshes/Link_arm_r_06.stl_0.stl"/></geometry></collision><collision><origin xyz="0.0 0.0 0.0" rpy="0.0 0.0 0.0"/><geometry><mesh filename="file:///home/tim/github/ROS/robot_decompose/openloong_description/meshes/Link_arm_r_06.stl_1.stl"/></geometry></collision><collision><origin xyz="0.0 0.0 0.0" rpy="0.0 0.0 0.0"/><geometry><mesh filename="file:///home/tim/github/ROS/robot_decompose/openloong_description/meshes/Link_arm_r_06.stl_2.stl"/></geometry></collision><collision><origin xyz="0.0 0.0 0.0" rpy="0.0 0.0 0.0"/><geometry><mesh filename="file:///home/tim/github/ROS/robot_decompose/openloong_description/meshes/Link_arm_r_06.stl_3.stl"/></geometry></collision><collision><origin xyz="0.0 0.0 0.0" rpy="0.0 0.0 0.0"/><geometry><mesh filename="file:///home/tim/github/ROS/robot_decompose/openloong_description/meshes/Link_arm_r_06.stl_4.stl"/></geometry></collision><collision><origin xyz="0.0 0.0 0.0" rpy="0.0 0.0 0.0"/><geometry><mesh filename="file:///home/tim/github/ROS/robot_decompose/openloong_description/meshes/Link_arm_r_06.stl_5.stl"/></geometry></collision><collision><origin xyz="0.0 0.0 0.0" rpy="0.0 0.0 0.0"/><geometry><mesh filename="file:///home/tim/github/ROS/robot_decompose/openloong_description/meshes/Link_arm_r_06.stl_6.stl"/></geometry></collision><collision><origin xyz="0.0 0.0 0.0" rpy="0.0 0.0 0.0"/><geometry><mesh filename="file:///home/tim/github/ROS/robot_decompose/openloong_description/meshes/Link_arm_r_06.stl_7.stl"/></geometry></collision><collision><origin xyz="0.0 0.0 0.0" rpy="0.0 0.0 0.0"/><geometry><mesh filename="file:///home/tim/github/ROS/robot_decompose/openloong_description/meshes/Link_arm_r_06.stl_8.stl"/></geometry></collision><collision><origin xyz="0.0 0.0 0.0" rpy="0.0 0.0 0.0"/><geometry><mesh filename="file:///home/tim/github/ROS/robot_decompose/openloong_description/meshes/Link_arm_r_06.stl_9.stl"/></geometry></collision><collision><origin xyz="0.0 0.0 0.0" rpy="0.0 0.0 0.0"/><geometry><mesh filename="file:///home/tim/github/ROS/robot_decompose/openloong_description/meshes/Link_arm_r_06.stl_10.stl"/></geometry></collision><collision><origin xyz="0.0 0.0 0.0" rpy="0.0 0.0 0.0"/><geometry><mesh filename="file:///home/tim/github/ROS/robot_decompose/openloong_description/meshes/Link_arm_r_06.stl_11.stl"/></geometry></collision><collision><origin xyz="0.0 0.0 0.0" rpy="0.0 0.0 0.0"/><geometry><mesh filename="file:///home/tim/github/ROS/robot_decompose/openloong_description/meshes/Link_arm_r_06.stl_12.stl"/></geometry></collision><collision><origin xyz="0.0 0.0 0.0" rpy="0.0 0.0 0.0"/><geometry><mesh filename="file:///home/tim/github/ROS/robot_decompose/openloong_description/meshes/Link_arm_r_06.stl_13.stl"/></geometry></collision><collision><origin xyz="0.0 0.0 0.0" rpy="0.0 0.0 0.0"/><geometry><mesh filename="file:///home/tim/github/ROS/robot_decompose/openloong_description/meshes/Link_arm_r_06.stl_14.stl"/></geometry></collision><collision><origin xyz="0.0 0.0 0.0" rpy="0.0 0.0 0.0"/><geometry><mesh filename="file:///home/tim/github/ROS/robot_decompose/openloong_description/meshes/Link_arm_r_06.stl_15.stl"/></geometry></collision><collision><origin xyz="0.0 0.0 0.0" rpy="0.0 0.0 0.0"/><geometry><mesh filename="file:///home/tim/github/ROS/robot_decompose/openloong_description/meshes/Link_arm_r_06.stl_16.stl"/></geometry></collision><collision><origin xyz="0.0 0.0 0.0" rpy="0.0 0.0 0.0"/><geometry><mesh filename="file:///home/tim/github/ROS/robot_decompose/openloong_description/meshes/Link_arm_r_06.stl_17.stl"/></geometry></collision><collision><origin xyz="0.0 0.0 0.0" rpy="0.0 0.0 0.0"/><geometry><mesh filename="file:///home/tim/github/ROS/robot_decompose/openloong_description/meshes/Link_arm_r_06.stl_18.stl"/></geometry></collision><collision><origin xyz="0.0 0.0 0.0" rpy="0.0 0.0 0.0"/><geometry><mesh filename="file:///home/tim/github/ROS/robot_decompose/openloong_description/meshes/Link_arm_r_06.stl_19.stl"/></geometry></collision><collision><origin xyz="0.0 0.0 0.0" rpy="0.0 0.0 0.0"/><geometry><mesh filename="file:///home/tim/github/ROS/robot_decompose/openloong_description/meshes/Link_arm_r_06.stl_20.stl"/></geometry></collision><collision><origin xyz="0.0 0.0 0.0" rpy="0.0 0.0 0.0"/><geometry><mesh filename="file:///home/tim/github/ROS/robot_decompose/openloong_description/meshes/Link_arm_r_06.stl_21.stl"/></geometry></collision><collision><origin xyz="0.0 0.0 0.0" rpy="0.0 0.0 0.0"/><geometry><mesh filename="file:///home/tim/github/ROS/robot_decompose/openloong_description/meshes/Link_arm_r_06.stl_22.stl"/></geometry></collision><collision><origin xyz="0.0 0.0 0.0" rpy="0.0 0.0 0.0"/><geometry><mesh filename="file:///home/tim/github/ROS/robot_decompose/openloong_description/meshes/Link_arm_r_06.stl_23.stl"/></geometry></collision><collision><origin xyz="0.0 0.0 0.0" rpy="0.0 0.0 0.0"/><geometry><mesh filename="file:///home/tim/github/ROS/robot_decompose/openloong_description/meshes/Link_arm_r_06.stl_24.stl"/></geometry></collision><collision><origin xyz="0.0 0.0 0.0" rpy="0.0 0.0 0.0"/><geometry><mesh filename="file:///home/tim/github/ROS/robot_decompose/openloong_description/meshes/Link_arm_r_06.stl_25.stl"/></geometry></collision><collision><origin xyz="0.0 0.0 0.0" rpy="0.0 0.0 0.0"/><geometry><mesh filename="file:///home/tim/github/ROS/robot_decompose/openloong_description/meshes/Link_arm_r_06.stl_26.stl"/></geometry></collision></link>
  <joint name="J_arm_r_06" type="revolute">
    <origin xyz="-0.0265 -0.1965 0.0" rpy="0.0 0.0 0.0"/>
    <axis xyz="1.0 0.0 0.0"/>
    <parent link="Link_arm_r_05"/>
    <child link="Link_arm_r_06"/>
    <limit effort="12.4" lower="-1.8326" upper="1.8326" velocity="6.28"/>
  </joint>
  <link name="Link_arm_r_07">
    <inertial>
      <origin xyz="-0.007859 -0.15817 -0.027736" rpy="0.0 0.0 0.0"/>
      <mass value="0.61354"/>
      <inertia ixx="0.0025969" ixy="4.65e-05" ixz="-0.0001089" iyy="0.0007306" iyz="-1.47e-05" izz="0.0030104"/>
    </inertial>
    <visual>
      <origin xyz="0.0 0.0 0.0" rpy="0.0 0.0 0.0"/>
      <geometry>
        <mesh filename="package://openloong_description/meshes/Link_arm_r_07.stl"/>
      </geometry>
      <material name="">
        <color rgba="0.77647 0.75686 0.73725 1.0"/>
      </material>
    </visual>
    <collision><origin xyz="0.0 0.0 0.0" rpy="0.0 0.0 0.0"/><geometry><mesh filename="file:///home/tim/github/ROS/robot_decompose/openloong_description/meshes/Link_arm_r_07.stl_0.stl"/></geometry></collision><collision><origin xyz="0.0 0.0 0.0" rpy="0.0 0.0 0.0"/><geometry><mesh filename="file:///home/tim/github/ROS/robot_decompose/openloong_description/meshes/Link_arm_r_07.stl_1.stl"/></geometry></collision><collision><origin xyz="0.0 0.0 0.0" rpy="0.0 0.0 0.0"/><geometry><mesh filename="file:///home/tim/github/ROS/robot_decompose/openloong_description/meshes/Link_arm_r_07.stl_2.stl"/></geometry></collision></link>
  <joint name="J_arm_r_07" type="revolute">
    <origin xyz="0.0265 0.0 0.0318" rpy="0.0 0.0 0.0"/>
    <axis xyz="0.0 0.0 1.0"/>
    <parent link="Link_arm_r_06"/>
    <child link="Link_arm_r_07"/>
    <limit effort="12.4" lower="-1.0472" upper="1.0472" velocity="6.28"/>
  </joint>
  <link name="Link_arm_l_01">
    <inertial>
      <origin xyz="-0.00449464987882542 0.0382942125981936 -1.874402432607e-06" rpy="0.0 0.0 0.0"/>
      <mass value="0.756406339732892"/>
      <inertia ixx="0.000587115683146372" ixy="-2.98026052651538e-07" ixz="5.83781087215966e-09" iyy="0.000803052813361661" iyz="-3.66476835396106e-08" izz="0.000842985653484675"/>
    </inertial>
    <visual>
      <origin xyz="0.0 0.0 0.0" rpy="0.0 0.0 0.0"/>
      <geometry>
        <mesh filename="package://openloong_description/meshes/Link_arm_l_01.stl"/>
      </geometry>
      <material name="">
        <color rgba="0.698039215686274 0.698039215686274 0.698039215686274 1.0"/>
      </material>
    </visual>
    <collision><origin xyz="0.0 0.0 0.0" rpy="0.0 0.0 0.0"/><geometry><mesh filename="file:///home/tim/github/ROS/robot_decompose/openloong_description/meshes/Link_arm_l_01.stl_0.stl"/></geometry></collision><collision><origin xyz="0.0 0.0 0.0" rpy="0.0 0.0 0.0"/><geometry><mesh filename="file:///home/tim/github/ROS/robot_decompose/openloong_description/meshes/Link_arm_l_01.stl_1.stl"/></geometry></collision><collision><origin xyz="0.0 0.0 0.0" rpy="0.0 0.0 0.0"/><geometry><mesh filename="file:///home/tim/github/ROS/robot_decompose/openloong_description/meshes/Link_arm_l_01.stl_2.stl"/></geometry></collision><collision><origin xyz="0.0 0.0 0.0" rpy="0.0 0.0 0.0"/><geometry><mesh filename="file:///home/tim/github/ROS/robot_decompose/openloong_description/meshes/Link_arm_l_01.stl_3.stl"/></geometry></collision><collision><origin xyz="0.0 0.0 0.0" rpy="0.0 0.0 0.0"/><geometry><mesh filename="file:///home/tim/github/ROS/robot_decompose/openloong_description/meshes/Link_arm_l_01.stl_4.stl"/></geometry></collision><collision><origin xyz="0.0 0.0 0.0" rpy="0.0 0.0 0.0"/><geometry><mesh filename="file:///home/tim/github/ROS/robot_decompose/openloong_description/meshes/Link_arm_l_01.stl_5.stl"/></geometry></collision><collision><origin xyz="0.0 0.0 0.0" rpy="0.0 0.0 0.0"/><geometry><mesh filename="file:///home/tim/github/ROS/robot_decompose/openloong_description/meshes/Link_arm_l_01.stl_6.stl"/></geometry></collision><collision><origin xyz="0.0 0.0 0.0" rpy="0.0 0.0 0.0"/><geometry><mesh filename="file:///home/tim/github/ROS/robot_decompose/openloong_description/meshes/Link_arm_l_01.stl_7.stl"/></geometry></collision><collision><origin xyz="0.0 0.0 0.0" rpy="0.0 0.0 0.0"/><geometry><mesh filename="file:///home/tim/github/ROS/robot_decompose/openloong_description/meshes/Link_arm_l_01.stl_8.stl"/></geometry></collision><collision><origin xyz="0.0 0.0 0.0" rpy="0.0 0.0 0.0"/><geometry><mesh filename="file:///home/tim/github/ROS/robot_decompose/openloong_description/meshes/Link_arm_l_01.stl_9.stl"/></geometry></collision><collision><origin xyz="0.0 0.0 0.0" rpy="0.0 0.0 0.0"/><geometry><mesh filename="file:///home/tim/github/ROS/robot_decompose/openloong_description/meshes/Link_arm_l_01.stl_10.stl"/></geometry></collision><collision><origin xyz="0.0 0.0 0.0" rpy="0.0 0.0 0.0"/><geometry><mesh filename="file:///home/tim/github/ROS/robot_decompose/openloong_description/meshes/Link_arm_l_01.stl_11.stl"/></geometry></collision><collision><origin xyz="0.0 0.0 0.0" rpy="0.0 0.0 0.0"/><geometry><mesh filename="file:///home/tim/github/ROS/robot_decompose/openloong_description/meshes/Link_arm_l_01.stl_12.stl"/></geometry></collision><collision><origin xyz="0.0 0.0 0.0" rpy="0.0 0.0 0.0"/><geometry><mesh filename="file:///home/tim/github/ROS/robot_decompose/openloong_description/meshes/Link_arm_l_01.stl_13.stl"/></geometry></collision><collision><origin xyz="0.0 0.0 0.0" rpy="0.0 0.0 0.0"/><geometry><mesh filename="file:///home/tim/github/ROS/robot_decompose/openloong_description/meshes/Link_arm_l_01.stl_14.stl"/></geometry></collision><collision><origin xyz="0.0 0.0 0.0" rpy="0.0 0.0 0.0"/><geometry><mesh filename="file:///home/tim/github/ROS/robot_decompose/openloong_description/meshes/Link_arm_l_01.stl_15.stl"/></geometry></collision><collision><origin xyz="0.0 0.0 0.0" rpy="0.0 0.0 0.0"/><geometry><mesh filename="file:///home/tim/github/ROS/robot_decompose/openloong_description/meshes/Link_arm_l_01.stl_16.stl"/></geometry></collision><collision><origin xyz="0.0 0.0 0.0" rpy="0.0 0.0 0.0"/><geometry><mesh filename="file:///home/tim/github/ROS/robot_decompose/openloong_description/meshes/Link_arm_l_01.stl_17.stl"/></geometry></collision><collision><origin xyz="0.0 0.0 0.0" rpy="0.0 0.0 0.0"/><geometry><mesh filename="file:///home/tim/github/ROS/robot_decompose/openloong_description/meshes/Link_arm_l_01.stl_18.stl"/></geometry></collision><collision><origin xyz="0.0 0.0 0.0" rpy="0.0 0.0 0.0"/><geometry><mesh filename="file:///home/tim/github/ROS/robot_decompose/openloong_description/meshes/Link_arm_l_01.stl_19.stl"/></geometry></collision><collision><origin xyz="0.0 0.0 0.0" rpy="0.0 0.0 0.0"/><geometry><mesh filename="file:///home/tim/github/ROS/robot_decompose/openloong_description/meshes/Link_arm_l_01.stl_20.stl"/></geometry></collision><collision><origin xyz="0.0 0.0 0.0" rpy="0.0 0.0 0.0"/><geometry><mesh filename="file:///home/tim/github/ROS/robot_decompose/openloong_description/meshes/Link_arm_l_01.stl_21.stl"/></geometry></collision><collision><origin xyz="0.0 0.0 0.0" rpy="0.0 0.0 0.0"/><geometry><mesh filename="file:///home/tim/github/ROS/robot_decompose/openloong_description/meshes/Link_arm_l_01.stl_22.stl"/></geometry></collision><collision><origin xyz="0.0 0.0 0.0" rpy="0.0 0.0 0.0"/><geometry><mesh filename="file:///home/tim/github/ROS/robot_decompose/openloong_description/meshes/Link_arm_l_01.stl_23.stl"/></geometry></collision><collision><origin xyz="0.0 0.0 0.0" rpy="0.0 0.0 0.0"/><geometry><mesh filename="file:///home/tim/github/ROS/robot_decompose/openloong_description/meshes/Link_arm_l_01.stl_24.stl"/></geometry></collision><collision><origin xyz="0.0 0.0 0.0" rpy="0.0 0.0 0.0"/><geometry><mesh filename="file:///home/tim/github/ROS/robot_decompose/openloong_description/meshes/Link_arm_l_01.stl_25.stl"/></geometry></collision><collision><origin xyz="0.0 0.0 0.0" rpy="0.0 0.0 0.0"/><geometry><mesh filename="file:///home/tim/github/ROS/robot_decompose/openloong_description/meshes/Link_arm_l_01.stl_26.stl"/></geometry></collision></link>
  <joint name="J_arm_l_01" type="revolute">
    <origin xyz="0.004 0.1616 0.3922" rpy="0.0 0.0 0.0"/>
    <axis xyz="0.0 1.0 0.0"/>
    <parent link="base_link"/>
    <child link="Link_arm_l_01"/>
    <limit effort="80.0" lower="-2.96706" upper="2.96706" velocity="3.14"/>
  </joint>
  <link name="Link_arm_l_02">
    <inertial>
      <origin xyz="-0.042 0.0674307499121858 1.38777878078145e-17" rpy="0.0 0.0 0.0"/>
      <mass value="0.984999996273518"/>
      <inertia ixx="0.0017309882399251" ixy="1.48322871384691e-19" ixz="1.94588987195478e-19" iyy="0.00115401958000568" iyz="6.15989345249147e-19" izz="0.00226269324370836"/>
    </inertial>
    <visual>
      <origin xyz="0.0 0.0 0.0" rpy="0.0 0.0 0.0"/>
      <geometry>
        <mesh filename="package://openloong_description/meshes/Link_arm_l_02.stl"/>
      </geometry>
      <material name="">
        <color rgba="0.698039215686274 0.698039215686274 0.698039215686274 1.0"/>
      </material>
    </visual>
    <collision><origin xyz="0.0 0.0 0.0" rpy="0.0 0.0 0.0"/><geometry><mesh filename="file:///home/tim/github/ROS/robot_decompose/openloong_description/meshes/Link_arm_l_02.stl_0.stl"/></geometry></collision><collision><origin xyz="0.0 0.0 0.0" rpy="0.0 0.0 0.0"/><geometry><mesh filename="file:///home/tim/github/ROS/robot_decompose/openloong_description/meshes/Link_arm_l_02.stl_1.stl"/></geometry></collision><collision><origin xyz="0.0 0.0 0.0" rpy="0.0 0.0 0.0"/><geometry><mesh filename="file:///home/tim/github/ROS/robot_decompose/openloong_description/meshes/Link_arm_l_02.stl_2.stl"/></geometry></collision><collision><origin xyz="0.0 0.0 0.0" rpy="0.0 0.0 0.0"/><geometry><mesh filename="file:///home/tim/github/ROS/robot_decompose/openloong_description/meshes/Link_arm_l_02.stl_3.stl"/></geometry></collision></link>
  <joint name="J_arm_l_02" type="revolute">
    <origin xyz="0.042 0.041 0.0" rpy="0.0 0.0 0.0"/>
    <axis xyz="-1.0 0.0 0.0"/>
    <parent link="Link_arm_l_01"/>
    <child link="Link_arm_l_02"/>
    <limit effort="80.0" lower="-1.8326" upper="1.8326" velocity="3.14"/>
  </joint>
  <link name="Link_arm_l_03">
    <inertial>
      <origin xyz="0.00141357502419956 0.164662742175383 0.0207578924800774" rpy="0.0 0.0 0.0"/>
      <mass value="0.958999855228925"/>
      <inertia ixx="0.00206438134078715" ixy="-1.82014067823508e-05" ixz="-5.12831369639908e-06" iyy="0.000805354129266641" iyz="-0.000255265992194607" izz="0.00205099914609259"/>
    </inertial>
    <visual>
      <origin xyz="0.0 0.0 0.0" rpy="0.0 0.0 0.0"/>
      <geometry>
        <mesh filename="package://openloong_description/meshes/Link_arm_l_03.stl"/>
      </geometry>
      <material name="">
        <color rgba="0.698039215686274 0.698039215686274 0.698039215686274 1.0"/>
      </material>
    </visual>
    <collision><origin xyz="0.0 0.0 0.0" rpy="0.0 0.0 0.0"/><geometry><mesh filename="file:///home/tim/github/ROS/robot_decompose/openloong_description/meshes/Link_arm_l_03.stl_0.stl"/></geometry></collision><collision><origin xyz="0.0 0.0 0.0" rpy="0.0 0.0 0.0"/><geometry><mesh filename="file:///home/tim/github/ROS/robot_decompose/openloong_description/meshes/Link_arm_l_03.stl_1.stl"/></geometry></collision></link>
  <joint name="J_arm_l_03" type="revolute">
    <origin xyz="-0.042 0.1226 0.0" rpy="0.0 0.0 0.0"/>
    <axis xyz="0.0 1.0 0.0"/>
    <parent link="Link_arm_l_02"/>
    <child link="Link_arm_l_03"/>
    <limit effort="48.0" lower="-2.96706" upper="2.96706" velocity="3.14"/>
  </joint>
  <link name="Link_arm_l_04">
    <inertial>
      <origin xyz="0.038726985904266 0.0607672244593032 -0.0210032450980798" rpy="0.0 0.0 0.0"/>
      <mass value="0.60000012303258"/>
      <inertia ixx="0.000703976141425558" ixy="2.02301178076816e-05" ixz="-1.12633779930363e-05" iyy="0.000680850033983237" iyz="0.000105852227353173" izz="0.00106526266740194"/>
    </inertial>
    <visual>
      <origin xyz="0.0 0.0 0.0" rpy="0.0 0.0 0.0"/>
      <geometry>
        <mesh filename="package://openloong_description/meshes/Link_arm_l_04.stl"/>
      </geometry>
      <material name="">
        <color rgba="0.698039215686274 0.698039215686274 0.698039215686274 1.0"/>
      </material>
    </visual>
    <collision><origin xyz="0.0 0.0 0.0" rpy="0.0 0.0 0.0"/><geometry><mesh filename="file:///home/tim/github/ROS/robot_decompose/openloong_description/meshes/Link_arm_l_04.stl_0.stl"/></geometry></collision><collision><origin xyz="0.0 0.0 0.0" rpy="0.0 0.0 0.0"/><geometry><mesh filename="file:///home/tim/github/ROS/robot_decompose/openloong_description/meshes/Link_arm_l_04.stl_1.stl"/></geometry></collision><collision><origin xyz="0.0 0.0 0.0" rpy="0.0 0.0 0.0"/><geometry><mesh filename="file:///home/tim/github/ROS/robot_decompose/openloong_description/meshes/Link_arm_l_04.stl_2.stl"/></geometry></collision><collision><origin xyz="0.0 0.0 0.0" rpy="0.0 0.0 0.0"/><geometry><mesh filename="file:///home/tim/github/ROS/robot_decompose/openloong_description/meshes/Link_arm_l_04.stl_3.stl"/></geometry></collision><collision><origin xyz="0.0 0.0 0.0" rpy="0.0 0.0 0.0"/><geometry><mesh filename="file:///home/tim/github/ROS/robot_decompose/openloong_description/meshes/Link_arm_l_04.stl_4.stl"/></geometry></collision><collision><origin xyz="0.0 0.0 0.0" rpy="0.0 0.0 0.0"/><geometry><mesh filename="file:///home/tim/github/ROS/robot_decompose/openloong_description/meshes/Link_arm_l_04.stl_5.stl"/></geometry></collision><collision><origin xyz="0.0 0.0 0.0" rpy="0.0 0.0 0.0"/><geometry><mesh filename="file:///home/tim/github/ROS/robot_decompose/openloong_description/meshes/Link_arm_l_04.stl_6.stl"/></geometry></collision></link>
  <joint name="J_arm_l_04" type="revolute">
    <origin xyz="-0.0353 0.1774 0.024" rpy="0.0 0.0 0.0"/>
    <axis xyz="1.0 0.0 0.0"/>
    <parent link="Link_arm_l_03"/>
    <child link="Link_arm_l_04"/>
    <limit effort="48.0" lower="0.0" upper="2.96706" velocity="3.14"/>
  </joint>
  <link name="Link_arm_l_05">
    <inertial>
      <origin xyz="-3.2712e-05 0.068658 -0.00011178" rpy="0.0 0.0 0.0"/>
      <mass value="0.68976"/>
      <inertia ixx="0.0025225" ixy="-4e-07" ixz="-8e-07" iyy="0.0004487" iyz="-3.1e-06" izz="0.0024111"/>
    </inertial>
    <visual>
      <origin xyz="0.0 0.0 0.0" rpy="0.0 0.0 0.0"/>
      <geometry>
        <mesh filename="package://openloong_description/meshes/Link_arm_l_05.stl"/>
      </geometry>
      <material name="">
        <color rgba="0.69804 0.69804 0.69804 1.0"/>
      </material>
    </visual>
    <collision><origin xyz="0.0 0.0 0.0" rpy="0.0 0.0 0.0"/><geometry><mesh filename="file:///home/tim/github/ROS/robot_decompose/openloong_description/meshes/Link_arm_l_05.stl_0.stl"/></geometry></collision><collision><origin xyz="0.0 0.0 0.0" rpy="0.0 0.0 0.0"/><geometry><mesh filename="file:///home/tim/github/ROS/robot_decompose/openloong_description/meshes/Link_arm_l_05.stl_1.stl"/></geometry></collision><collision><origin xyz="0.0 0.0 0.0" rpy="0.0 0.0 0.0"/><geometry><mesh filename="file:///home/tim/github/ROS/robot_decompose/openloong_description/meshes/Link_arm_l_05.stl_2.stl"/></geometry></collision><collision><origin xyz="0.0 0.0 0.0" rpy="0.0 0.0 0.0"/><geometry><mesh filename="file:///home/tim/github/ROS/robot_decompose/openloong_description/meshes/Link_arm_l_05.stl_3.stl"/></geometry></collision><collision><origin xyz="0.0 0.0 0.0" rpy="0.0 0.0 0.0"/><geometry><mesh filename="file:///home/tim/github/ROS/robot_decompose/openloong_description/meshes/Link_arm_l_05.stl_4.stl"/></geometry></collision><collision><origin xyz="0.0 0.0 0.0" rpy="0.0 0.0 0.0"/><geometry><mesh filename="file:///home/tim/github/ROS/robot_decompose/openloong_description/meshes/Link_arm_l_05.stl_5.stl"/></geometry></collision></link>
  <joint name="J_arm_l_05" type="revolute">
    <origin xyz="0.0353 0.1035 -0.024" rpy="0.0 0.0 0.0"/>
    <axis xyz="0.0 1.0 0.0"/>
    <parent link="Link_arm_l_04"/>
    <child link="Link_arm_l_05"/>
    <limit effort="12.4" lower="-2.96706" upper="2.96706" velocity="6.28"/>
  </joint>
  <link name="Link_arm_l_06">
    <inertial>
      <origin xyz="-0.0260776548825596 8.95877202866657e-07 0.00166373234012217" rpy="0.0 0.0 0.0"/>
      <mass value="0.280000012776158"/>
      <inertia ixx="0.000145596926990102" ixy="-7.70263046256849e-10" ixz="2.14557176368931e-07" iyy="0.000156926535065694" iyz="2.41022657678511e-09" izz="0.000104981940665913"/>
    </inertial>
    <visual>
      <origin xyz="0.0 0.0 0.0" rpy="0.0 0.0 0.0"/>
      <geometry>
        <mesh filename="package://openloong_description/meshes/Link_arm_l_06.stl"/>
      </geometry>
      <material name="">
        <color rgba="0.698039215686274 0.698039215686274 0.698039215686274 1.0"/>
      </material>
    </visual>
    <collision><origin xyz="0.0 0.0 0.0" rpy="0.0 0.0 0.0"/><geometry><mesh filename="file:///home/tim/github/ROS/robot_decompose/openloong_description/meshes/Link_arm_l_06.stl_0.stl"/></geometry></collision><collision><origin xyz="0.0 0.0 0.0" rpy="0.0 0.0 0.0"/><geometry><mesh filename="file:///home/tim/github/ROS/robot_decompose/openloong_description/meshes/Link_arm_l_06.stl_1.stl"/></geometry></collision><collision><origin xyz="0.0 0.0 0.0" rpy="0.0 0.0 0.0"/><geometry><mesh filename="file:///home/tim/github/ROS/robot_decompose/openloong_description/meshes/Link_arm_l_06.stl_2.stl"/></geometry></collision><collision><origin xyz="0.0 0.0 0.0" rpy="0.0 0.0 0.0"/><geometry><mesh filename="file:///home/tim/github/ROS/robot_decompose/openloong_description/meshes/Link_arm_l_06.stl_3.stl"/></geometry></collision><collision><origin xyz="0.0 0.0 0.0" rpy="0.0 0.0 0.0"/><geometry><mesh filename="file:///home/tim/github/ROS/robot_decompose/openloong_description/meshes/Link_arm_l_06.stl_4.stl"/></geometry></collision><collision><origin xyz="0.0 0.0 0.0" rpy="0.0 0.0 0.0"/><geometry><mesh filename="file:///home/tim/github/ROS/robot_decompose/openloong_description/meshes/Link_arm_l_06.stl_5.stl"/></geometry></collision><collision><origin xyz="0.0 0.0 0.0" rpy="0.0 0.0 0.0"/><geometry><mesh filename="file:///home/tim/github/ROS/robot_decompose/openloong_description/meshes/Link_arm_l_06.stl_6.stl"/></geometry></collision><collision><origin xyz="0.0 0.0 0.0" rpy="0.0 0.0 0.0"/><geometry><mesh filename="file:///home/tim/github/ROS/robot_decompose/openloong_description/meshes/Link_arm_l_06.stl_7.stl"/></geometry></collision><collision><origin xyz="0.0 0.0 0.0" rpy="0.0 0.0 0.0"/><geometry><mesh filename="file:///home/tim/github/ROS/robot_decompose/openloong_description/meshes/Link_arm_l_06.stl_8.stl"/></geometry></collision><collision><origin xyz="0.0 0.0 0.0" rpy="0.0 0.0 0.0"/><geometry><mesh filename="file:///home/tim/github/ROS/robot_decompose/openloong_description/meshes/Link_arm_l_06.stl_9.stl"/></geometry></collision><collision><origin xyz="0.0 0.0 0.0" rpy="0.0 0.0 0.0"/><geometry><mesh filename="file:///home/tim/github/ROS/robot_decompose/openloong_description/meshes/Link_arm_l_06.stl_10.stl"/></geometry></collision><collision><origin xyz="0.0 0.0 0.0" rpy="0.0 0.0 0.0"/><geometry><mesh filename="file:///home/tim/github/ROS/robot_decompose/openloong_description/meshes/Link_arm_l_06.stl_11.stl"/></geometry></collision><collision><origin xyz="0.0 0.0 0.0" rpy="0.0 0.0 0.0"/><geometry><mesh filename="file:///home/tim/github/ROS/robot_decompose/openloong_description/meshes/Link_arm_l_06.stl_12.stl"/></geometry></collision><collision><origin xyz="0.0 0.0 0.0" rpy="0.0 0.0 0.0"/><geometry><mesh filename="file:///home/tim/github/ROS/robot_decompose/openloong_description/meshes/Link_arm_l_06.stl_13.stl"/></geometry></collision><collision><origin xyz="0.0 0.0 0.0" rpy="0.0 0.0 0.0"/><geometry><mesh filename="file:///home/tim/github/ROS/robot_decompose/openloong_description/meshes/Link_arm_l_06.stl_14.stl"/></geometry></collision><collision><origin xyz="0.0 0.0 0.0" rpy="0.0 0.0 0.0"/><geometry><mesh filename="file:///home/tim/github/ROS/robot_decompose/openloong_description/meshes/Link_arm_l_06.stl_15.stl"/></geometry></collision><collision><origin xyz="0.0 0.0 0.0" rpy="0.0 0.0 0.0"/><geometry><mesh filename="file:///home/tim/github/ROS/robot_decompose/openloong_description/meshes/Link_arm_l_06.stl_16.stl"/></geometry></collision><collision><origin xyz="0.0 0.0 0.0" rpy="0.0 0.0 0.0"/><geometry><mesh filename="file:///home/tim/github/ROS/robot_decompose/openloong_description/meshes/Link_arm_l_06.stl_17.stl"/></geometry></collision><collision><origin xyz="0.0 0.0 0.0" rpy="0.0 0.0 0.0"/><geometry><mesh filename="file:///home/tim/github/ROS/robot_decompose/openloong_description/meshes/Link_arm_l_06.stl_18.stl"/></geometry></collision><collision><origin xyz="0.0 0.0 0.0" rpy="0.0 0.0 0.0"/><geometry><mesh filename="file:///home/tim/github/ROS/robot_decompose/openloong_description/meshes/Link_arm_l_06.stl_19.stl"/></geometry></collision><collision><origin xyz="0.0 0.0 0.0" rpy="0.0 0.0 0.0"/><geometry><mesh filename="file:///home/tim/github/ROS/robot_decompose/openloong_description/meshes/Link_arm_l_06.stl_20.stl"/></geometry></collision><collision><origin xyz="0.0 0.0 0.0" rpy="0.0 0.0 0.0"/><geometry><mesh filename="file:///home/tim/github/ROS/robot_decompose/openloong_description/meshes/Link_arm_l_06.stl_21.stl"/></geometry></collision><collision><origin xyz="0.0 0.0 0.0" rpy="0.0 0.0 0.0"/><geometry><mesh filename="file:///home/tim/github/ROS/robot_decompose/openloong_description/meshes/Link_arm_l_06.stl_22.stl"/></geometry></collision><collision><origin xyz="0.0 0.0 0.0" rpy="0.0 0.0 0.0"/><geometry><mesh filename="file:///home/tim/github/ROS/robot_decompose/openloong_description/meshes/Link_arm_l_06.stl_23.stl"/></geometry></collision><collision><origin xyz="0.0 0.0 0.0" rpy="0.0 0.0 0.0"/><geometry><mesh filename="file:///home/tim/github/ROS/robot_decompose/openloong_description/meshes/Link_arm_l_06.stl_24.stl"/></geometry></collision><collision><origin xyz="0.0 0.0 0.0" rpy="0.0 0.0 0.0"/><geometry><mesh filename="file:///home/tim/github/ROS/robot_decompose/openloong_description/meshes/Link_arm_l_06.stl_25.stl"/></geometry></collision><collision><origin xyz="0.0 0.0 0.0" rpy="0.0 0.0 0.0"/><geometry><mesh filename="file:///home/tim/github/ROS/robot_decompose/openloong_description/meshes/Link_arm_l_06.stl_26.stl"/></geometry></collision></link>
  <joint name="J_arm_l_06" type="revolute">
    <origin xyz="0.0265 0.1965 0.0" rpy="0.0 0.0 0.0"/>
    <axis xyz="-1.0 0.0 0.0"/>
    <parent link="Link_arm_l_05"/>
    <child link="Link_arm_l_06"/>
    <limit effort="12.4" lower="-1.8326" upper="1.8326" velocity="6.28"/>
  </joint>
  <link name="Link_arm_l_07">
    <inertial>
      <origin xyz="-0.0077872 0.15705 -0.027733" rpy="0.0 0.0 0.0"/>
      <mass value="0.61354"/>
      <inertia ixx="0.0025964" ixy="-4.66e-05" ixz="-0.0001089" iyy="0.0007306" iyz="1.47e-05" izz="0.00301"/>
    </inertial>
    <visual>
      <origin xyz="0.0 0.0 0.0" rpy="0.0 0.0 0.0"/>
      <geometry>
        <mesh filename="package://openloong_description/meshes/Link_arm_l_07.stl"/>
      </geometry>
      <material name="">
        <color rgba="0.77647 0.75686 0.73725 1.0"/>
      </material>
    </visual>
    <collision><origin xyz="0.0 0.0 0.0" rpy="0.0 0.0 0.0"/><geometry><mesh filename="file:///home/tim/github/ROS/robot_decompose/openloong_description/meshes/Link_arm_l_07.stl_0.stl"/></geometry></collision><collision><origin xyz="0.0 0.0 0.0" rpy="0.0 0.0 0.0"/><geometry><mesh filename="file:///home/tim/github/ROS/robot_decompose/openloong_description/meshes/Link_arm_l_07.stl_1.stl"/></geometry></collision><collision><origin xyz="0.0 0.0 0.0" rpy="0.0 0.0 0.0"/><geometry><mesh filename="file:///home/tim/github/ROS/robot_decompose/openloong_description/meshes/Link_arm_l_07.stl_2.stl"/></geometry></collision></link>
  <joint name="J_arm_l_07" type="revolute">
    <origin xyz="-0.0265 0.0 0.0318" rpy="0.0 0.0 0.0"/>
    <axis xyz="0.0 0.0 1.0"/>
    <parent link="Link_arm_l_06"/>
    <child link="Link_arm_l_07"/>
    <limit effort="12.4" lower="-1.0472" upper="1.0472" velocity="6.28"/>
  </joint>
  <link name="Link_waist_pitch">
    <inertial>
      <origin xyz="-0.00073496 0.049925 -2.9695e-05" rpy="0.0 0.0 0.0"/>
      <mass value="2.6964"/>
      <inertia ixx="0.0051971" ixy="-4.37e-05" ixz="3e-07" iyy="0.0047413" iyz="6e-06" izz="0.0061906"/>
    </inertial>
    <visual>
      <origin xyz="0.0 0.0 0.0" rpy="0.0 0.0 0.0"/>
      <geometry>
        <mesh filename="package://openloong_description/meshes/Link_waist_pitch.stl"/>
      </geometry>
      <material name="">
        <color rgba="0.69804 0.69804 0.69804 1.0"/>
      </material>
    </visual>
    <collision><origin xyz="0.0 0.0 0.0" rpy="0.0 0.0 0.0"/><geometry><mesh filename="file:///home/tim/github/ROS/robot_decompose/openloong_description/meshes/Link_waist_pitch.stl_0.stl"/></geometry></collision><collision><origin xyz="0.0 0.0 0.0" rpy="0.0 0.0 0.0"/><geometry><mesh filename="file:///home/tim/github/ROS/robot_decompose/openloong_description/meshes/Link_waist_pitch.stl_1.stl"/></geometry></collision><collision><origin xyz="0.0 0.0 0.0" rpy="0.0 0.0 0.0"/><geometry><mesh filename="file:///home/tim/github/ROS/robot_decompose/openloong_description/meshes/Link_waist_pitch.stl_2.stl"/></geometry></collision><collision><origin xyz="0.0 0.0 0.0" rpy="0.0 0.0 0.0"/><geometry><mesh filename="file:///home/tim/github/ROS/robot_decompose/openloong_description/meshes/Link_waist_pitch.stl_3.stl"/></geometry></collision><collision><origin xyz="0.0 0.0 0.0" rpy="0.0 0.0 0.0"/><geometry><mesh filename="file:///home/tim/github/ROS/robot_decompose/openloong_description/meshes/Link_waist_pitch.stl_4.stl"/></geometry></collision><collision><origin xyz="0.0 0.0 0.0" rpy="0.0 0.0 0.0"/><geometry><mesh filename="file:///home/tim/github/ROS/robot_decompose/openloong_description/meshes/Link_waist_pitch.stl_5.stl"/></geometry></collision><collision><origin xyz="0.0 0.0 0.0" rpy="0.0 0.0 0.0"/><geometry><mesh filename="file:///home/tim/github/ROS/robot_decompose/openloong_description/meshes/Link_waist_pitch.stl_6.stl"/></geometry></collision><collision><origin xyz="0.0 0.0 0.0" rpy="0.0 0.0 0.0"/><geometry><mesh filename="file:///home/tim/github/ROS/robot_decompose/openloong_description/meshes/Link_waist_pitch.stl_7.stl"/></geometry></collision><collision><origin xyz="0.0 0.0 0.0" rpy="0.0 0.0 0.0"/><geometry><mesh filename="file:///home/tim/github/ROS/robot_decompose/openloong_description/meshes/Link_waist_pitch.stl_8.stl"/></geometry></collision><collision><origin xyz="0.0 0.0 0.0" rpy="0.0 0.0 0.0"/><geometry><mesh filename="file:///home/tim/github/ROS/robot_decompose/openloong_description/meshes/Link_waist_pitch.stl_9.stl"/></geometry></collision></link>
  <joint name="J_waist_pitch" type="revolute">
    <origin xyz="0.0 -0.06525 0.0" rpy="0.0 0.0 0.0"/>
    <axis xyz="0.0 -1.0 0.0"/>
    <parent link="base_link"/>
    <child link="Link_waist_pitch"/>
    <limit effort="315.0" lower="-0.29671" upper="0.7854" velocity="3.72"/>
  </joint>
  <link name="Link_waist_roll">
    <inertial>
      <origin xyz="-0.0037424 -0.001 -0.016856" rpy="0.0 0.0 0.0"/>
      <mass value="2.9806"/>
      <inertia ixx="0.0071327" ixy="0.0" ixz="-0.00358" iyy="0.018825" iyz="0.0" izz="0.016056"/>
    </inertial>
    <visual>
      <origin xyz="0.0 0.0 0.0" rpy="0.0 0.0 0.0"/>
      <geometry>
        <mesh filename="package://openloong_description/meshes/Link_waist_roll.stl"/>
      </geometry>
      <material name="">
        <color rgba="0.8902 0.8902 0.91373 1.0"/>
      </material>
    </visual>
    <collision><origin xyz="0.0 0.0 0.0" rpy="0.0 0.0 0.0"/><geometry><mesh filename="file:///home/tim/github/ROS/robot_decompose/openloong_description/meshes/Link_waist_roll.stl_0.stl"/></geometry></collision><collision><origin xyz="0.0 0.0 0.0" rpy="0.0 0.0 0.0"/><geometry><mesh filename="file:///home/tim/github/ROS/robot_decompose/openloong_description/meshes/Link_waist_roll.stl_1.stl"/></geometry></collision><collision><origin xyz="0.0 0.0 0.0" rpy="0.0 0.0 0.0"/><geometry><mesh filename="file:///home/tim/github/ROS/robot_decompose/openloong_description/meshes/Link_waist_roll.stl_2.stl"/></geometry></collision><collision><origin xyz="0.0 0.0 0.0" rpy="0.0 0.0 0.0"/><geometry><mesh filename="file:///home/tim/github/ROS/robot_decompose/openloong_description/meshes/Link_waist_roll.stl_3.stl"/></geometry></collision></link>
  <joint name="J_waist_roll" type="revolute">
    <origin xyz="-0.064 0.0655 0.0" rpy="0.0 0.0 0.0"/>
    <axis xyz="1.0 0.0 0.0"/>
    <parent link="Link_waist_pitch"/>
    <child link="Link_waist_roll"/>
    <limit effort="315.0" lower="-0.69813" upper="0.69813" velocity="3.72"/>
  </joint>
  <link name="Link_waist_yaw">
    <inertial>
      <origin xyz="-0.096172 -0.001 -0.057836" rpy="0.0 0.0 0.0"/>
      <mass value="7.3588"/>
      <inertia ixx="0.091635" ixy="0.0" ixz="0.0058036" iyy="0.032766" iyz="0.0" izz="0.10764"/>
    </inertial>
    <visual>
      <origin xyz="0.0 0.0 0.0" rpy="0.0 0.0 0.0"/>
      <geometry>
        <mesh filename="package://openloong_description/meshes/Link_waist_yaw.stl"/>
      </geometry>
      <material name="">
        <color rgba="0.8902 0.8902 0.91373 1.0"/>
      </material>
    </visual>
    <collision><origin xyz="0.0 0.0 0.0" rpy="0.0 0.0 0.0"/><geometry><mesh filename="file:///home/tim/github/ROS/robot_decompose/openloong_description/meshes/Link_waist_yaw.stl_0.stl"/></geometry></collision><collision><origin xyz="0.0 0.0 0.0" rpy="0.0 0.0 0.0"/><geometry><mesh filename="file:///home/tim/github/ROS/robot_decompose/openloong_description/meshes/Link_waist_yaw.stl_1.stl"/></geometry></collision><collision><origin xyz="0.0 0.0 0.0" rpy="0.0 0.0 0.0"/><geometry><mesh filename="file:///home/tim/github/ROS/robot_decompose/openloong_description/meshes/Link_waist_yaw.stl_2.stl"/></geometry></collision><collision><origin xyz="0.0 0.0 0.0" rpy="0.0 0.0 0.0"/><geometry><mesh filename="file:///home/tim/github/ROS/robot_decompose/openloong_description/meshes/Link_waist_yaw.stl_3.stl"/></geometry></collision></link>
  <joint name="J_waist_yaw" type="revolute">
    <origin xyz="0.0675 0.0 -0.098" rpy="0.0 0.0 0.0"/>
    <axis xyz="0.0 0.0 1.0"/>
    <parent link="Link_waist_roll"/>
    <child link="Link_waist_yaw"/>
    <limit effort="121.0" lower="-0.7854" upper="0.7854" velocity="5.92"/>
  </joint>
  <link name="Link_hip_r_roll">
    <inertial>
      <origin xyz="0.075725 -0.0010616 0.016591" rpy="0.0 0.0 0.0"/>
      <mass value="2.4334"/>
      <inertia ixx="0.0036961" ixy="-9e-07" ixz="0.0001644" iyy="0.0045067" iyz="6.3e-06" izz="0.0039063"/>
    </inertial>
    <visual>
      <origin xyz="0.0 0.0 0.0" rpy="0.0 0.0 0.0"/>
      <geometry>
        <mesh filename="package://openloong_description/meshes/Link_hip_r_roll.stl"/>
      </geometry>
      <material name="">
        <color rgba="0.89804 0.91765 0.92941 1.0"/>
      </material>
    </visual>
    <collision><origin xyz="0.0 0.0 0.0" rpy="0.0 0.0 0.0"/><geometry><mesh filename="file:///home/tim/github/ROS/robot_decompose/openloong_description/meshes/Link_hip_r_roll.stl_0.stl"/></geometry></collision><collision><origin xyz="0.0 0.0 0.0" rpy="0.0 0.0 0.0"/><geometry><mesh filename="file:///home/tim/github/ROS/robot_decompose/openloong_description/meshes/Link_hip_r_roll.stl_1.stl"/></geometry></collision><collision><origin xyz="0.0 0.0 0.0" rpy="0.0 0.0 0.0"/><geometry><mesh filename="file:///home/tim/github/ROS/robot_decompose/openloong_description/meshes/Link_hip_r_roll.stl_2.stl"/></geometry></collision><collision><origin xyz="0.0 0.0 0.0" rpy="0.0 0.0 0.0"/><geometry><mesh filename="file:///home/tim/github/ROS/robot_decompose/openloong_description/meshes/Link_hip_r_roll.stl_3.stl"/></geometry></collision><collision><origin xyz="0.0 0.0 0.0" rpy="0.0 0.0 0.0"/><geometry><mesh filename="file:///home/tim/github/ROS/robot_decompose/openloong_description/meshes/Link_hip_r_roll.stl_4.stl"/></geometry></collision><collision><origin xyz="0.0 0.0 0.0" rpy="0.0 0.0 0.0"/><geometry><mesh filename="file:///home/tim/github/ROS/robot_decompose/openloong_description/meshes/Link_hip_r_roll.stl_5.stl"/></geometry></collision><collision><origin xyz="0.0 0.0 0.0" rpy="0.0 0.0 0.0"/><geometry><mesh filename="file:///home/tim/github/ROS/robot_decompose/openloong_description/meshes/Link_hip_r_roll.stl_6.stl"/></geometry></collision></link>
  <joint name="J_hip_r_roll" type="revolute">
    <origin xyz="-0.0875 -0.12 -0.069" rpy="0.0 0.0 0.0"/>
    <axis xyz="1.0 0.0 0.0"/>
    <parent link="Link_waist_yaw"/>
    <child link="Link_hip_r_roll"/>
    <limit effort="320.0" lower="-0.17453" upper="0.43633" velocity="20.94"/>
  </joint>
  <link name="Link_hip_r_yaw">
    <inertial>
      <origin xyz="-3.0911e-08 -0.0071356 -0.10063" rpy="0.0 0.0 0.0"/>
      <mass value="3.4303"/>
      <inertia ixx="0.0077365" ixy="0.0" ixz="0.0" iyy="0.0080807" iyz="0.0001167" izz="0.006641"/>
    </inertial>
    <visual>
      <origin xyz="0.0 0.0 0.0" rpy="0.0 0.0 0.0"/>
      <geometry>
        <mesh filename="package://openloong_description/meshes/Link_hip_r_yaw.stl"/>
      </geometry>
      <material name="">
        <color rgba="0.89804 0.91765 0.92941 1.0"/>
      </material>
    </visual>
    <collision><origin xyz="0.0 0.0 0.0" rpy="0.0 0.0 0.0"/><geometry><mesh filename="file:///home/tim/github/ROS/robot_decompose/openloong_description/meshes/Link_hip_r_yaw.stl_0.stl"/></geometry></collision><collision><origin xyz="0.0 0.0 0.0" rpy="0.0 0.0 0.0"/><geometry><mesh filename="file:///home/tim/github/ROS/robot_decompose/openloong_description/meshes/Link_hip_r_yaw.stl_1.stl"/></geometry></collision><collision><origin xyz="0.0 0.0 0.0" rpy="0.0 0.0 0.0"/><geometry><mesh filename="file:///home/tim/github/ROS/robot_decompose/openloong_description/meshes/Link_hip_r_yaw.stl_2.stl"/></geometry></collision><collision><origin xyz="0.0 0.0 0.0" rpy="0.0 0.0 0.0"/><geometry><mesh filename="file:///home/tim/github/ROS/robot_decompose/openloong_description/meshes/Link_hip_r_yaw.stl_3.stl"/></geometry></collision><collision><origin xyz="0.0 0.0 0.0" rpy="0.0 0.0 0.0"/><geometry><mesh filename="file:///home/tim/github/ROS/robot_decompose/openloong_description/meshes/Link_hip_r_yaw.stl_4.stl"/></geometry></collision><collision><origin xyz="0.0 0.0 0.0" rpy="0.0 0.0 0.0"/><geometry><mesh filename="file:///home/tim/github/ROS/robot_decompose/openloong_description/meshes/Link_hip_r_yaw.stl_5.stl"/></geometry></collision></link>
  <joint name="J_hip_r_yaw" type="revolute">
    <origin xyz="0.08225 -0.001 -0.01" rpy="0.0 0.0 0.0"/>
    <axis xyz="0.0 0.0 1.0"/>
    <parent link="Link_hip_r_roll"/>
    <child link="Link_hip_r_yaw"/>
    <limit effort="160.0" lower="-0.69813" upper="0.69813" velocity="19.63"/>
  </joint>
  <link name="Link_hip_r_pitch">
    <inertial>
      <origin xyz="0.0010856 -0.05497 -0.14535" rpy="0.0 0.0 0.0"/>
      <mass value="5.2378"/>
      <inertia ixx="0.043457" ixy="0.0002478" ixz="-0.0007626" iyy="0.037801" iyz="-0.0007431" izz="0.015183"/>
    </inertial>
    <visual>
      <origin xyz="0.0 0.0 0.0" rpy="0.0 0.0 0.0"/>
      <geometry>
        <mesh filename="package://openloong_description/meshes/Link_hip_r_pitch.stl"/>
      </geometry>
      <material name="">
        <color rgba="0.69804 0.69804 0.69804 1.0"/>
      </material>
    </visual>
    <collision><origin xyz="0.0 0.0 0.0" rpy="0.0 0.0 0.0"/><geometry><mesh filename="file:///home/tim/github/ROS/robot_decompose/openloong_description/meshes/Link_hip_r_pitch.stl_0.stl"/></geometry></collision><collision><origin xyz="0.0 0.0 0.0" rpy="0.0 0.0 0.0"/><geometry><mesh filename="file:///home/tim/github/ROS/robot_decompose/openloong_description/meshes/Link_hip_r_pitch.stl_1.stl"/></geometry></collision></link>
  <joint name="J_hip_r_pitch" type="revolute">
    <origin xyz="0.0 0.03675 -0.1055" rpy="0.0 0.0 0.0"/>
    <axis xyz="0.0 -1.0 0.0"/>
    <parent link="Link_hip_r_yaw"/>
    <child link="Link_hip_r_pitch"/>
    <limit effort="396.0" lower="-0.7854" upper="1.8326" velocity="19.16"/>
  </joint>
  <link name="Link_knee_r_pitch">
    <inertial>
      <origin xyz="-0.0096425 2.9338e-06 -0.13601" rpy="0.0 0.0 0.0"/>
      <mass value="2.9775"/>
      <inertia ixx="0.02386" ixy="6.76e-05" ixz="-0.0004656" iyy="0.024184" iyz="-0.0005481" izz="0.0023083"/>
    </inertial>
    <visual>
      <origin xyz="0.0 0.0 0.0" rpy="0.0 0.0 0.0"/>
      <geometry>
        <mesh filename="package://openloong_description/meshes/Link_knee_r_pitch.stl"/>
      </geometry>
      <material name="">
        <color rgba="0.66667 0.69804 0.76863 1.0"/>
      </material>
    </visual>
    <collision><origin xyz="0.0 0.0 0.0" rpy="0.0 0.0 0.0"/><geometry><mesh filename="file:///home/tim/github/ROS/robot_decompose/openloong_description/meshes/Link_knee_r_pitch.stl_0.stl"/></geometry></collision></link>
  <joint name="J_knee_r_pitch" type="revolute">
    <origin xyz="0.0 -0.01125 -0.4" rpy="0.0 0.0 0.0"/>
    <axis xyz="0.0 -1.0 0.0"/>
    <parent link="Link_hip_r_pitch"/>
    <child link="Link_knee_r_pitch"/>
    <limit effort="396.0" lower="-2.35619" upper="0.08727" velocity="19.16"/>
  </joint>
  <link name="Link_ankle_r_pitch">
    <inertial>
      <origin xyz="-6.1835e-12 -1.2655e-07 -2.4682e-08" rpy="0.0 0.0 0.0"/>
      <mass value="0.10145"/>
      <inertia ixx="2.7175e-05" ixy="1.0023e-14" ixz="-8.1752e-13" iyy="6.1118e-06" iyz="2.6285e-11" izz="2.6565e-05"/>
    </inertial>
    <visual>
      <origin xyz="0.0 0.0 0.0" rpy="0.0 0.0 0.0"/>
      <geometry>
        <mesh filename="package://openloong_description/meshes/Link_ankle_r_pitch.stl"/>
      </geometry>
      <material name="">
        <color rgba="0.52941 0.54902 0.54902 1.0"/>
      </material>
    </visual>
    <collision><origin xyz="0.0 0.0 0.0" rpy="0.0 0.0 0.0"/><geometry><mesh filename="file:///home/tim/github/ROS/robot_decompose/openloong_description/meshes/Link_ankle_r_pitch.stl_0.stl"/></geometry></collision><collision><origin xyz="0.0 0.0 0.0" rpy="0.0 0.0 0.0"/><geometry><mesh filename="file:///home/tim/github/ROS/robot_decompose/openloong_description/meshes/Link_ankle_r_pitch.stl_1.stl"/></geometry></collision><collision><origin xyz="0.0 0.0 0.0" rpy="0.0 0.0 0.0"/><geometry><mesh filename="file:///home/tim/github/ROS/robot_decompose/openloong_description/meshes/Link_ankle_r_pitch.stl_2.stl"/></geometry></collision><collision><origin xyz="0.0 0.0 0.0" rpy="0.0 0.0 0.0"/><geometry><mesh filename="file:///home/tim/github/ROS/robot_decompose/openloong_description/meshes/Link_ankle_r_pitch.stl_3.stl"/></geometry></collision></link>
  <joint name="J_ankle_r_pitch" type="revolute">
    <origin xyz="0.0 0.0 -0.387" rpy="0.0 0.0 0.0"/>
    <axis xyz="0.0 -1.0 0.0"/>
    <parent link="Link_knee_r_pitch"/>
    <child link="Link_ankle_r_pitch"/>
    <limit effort="58.5" lower="-0.43633" upper="0.61087" velocity="48.8"/>
  </joint>
  <link name="Link_ankle_r_roll">
    <inertial>
      <origin xyz="0.041078 -8.9152e-08 -0.043909" rpy="0.0 0.0 0.0"/>
      <mass value="0.75229"/>
      <inertia ixx="0.0004393" ixy="0.0" ixz="-0.000269" iyy="0.0036465" iyz="0.0" izz="0.0036369"/>
    </inertial>
    <visual>
      <origin xyz="0.0 0.0 0.0" rpy="0.0 0.0 0.0"/>
      <geometry>
        <mesh filename="package://openloong_description/meshes/Link_ankle_r_roll.stl"/>
      </geometry>
      <material name="">
        <color rgba="0.89804 0.91765 0.92941 1.0"/>
      </material>
    </visual>
    <collision><origin xyz="0.0 0.0 0.0" rpy="0.0 0.0 0.0"/><geometry><mesh filename="file:///home/tim/github/ROS/robot_decompose/openloong_description/meshes/Link_ankle_r_roll.stl_0.stl"/></geometry></collision><collision><origin xyz="0.0 0.0 0.0" rpy="0.0 0.0 0.0"/><geometry><mesh filename="file:///home/tim/github/ROS/robot_decompose/openloong_description/meshes/Link_ankle_r_roll.stl_1.stl"/></geometry></collision><collision><origin xyz="0.0 0.0 0.0" rpy="0.0 0.0 0.0"/><geometry><mesh filename="file:///home/tim/github/ROS/robot_decompose/openloong_description/meshes/Link_ankle_r_roll.stl_2.stl"/></geometry></collision><collision><origin xyz="0.0 0.0 0.0" rpy="0.0 0.0 0.0"/><geometry><mesh filename="file:///home/tim/github/ROS/robot_decompose/openloong_description/meshes/Link_ankle_r_roll.stl_3.stl"/></geometry></collision><collision><origin xyz="0.0 0.0 0.0" rpy="0.0 0.0 0.0"/><geometry><mesh filename="file:///home/tim/github/ROS/robot_decompose/openloong_description/meshes/Link_ankle_r_roll.stl_4.stl"/></geometry></collision></link>
  <joint name="J_ankle_r_roll" type="revolute">
    <origin xyz="0.0 0.0 0.0" rpy="0.0 0.0 0.0"/>
    <axis xyz="1.0 0.0 0.0"/>
    <parent link="Link_ankle_r_pitch"/>
    <child link="Link_ankle_r_roll"/>
    <limit effort="58.5" lower="-0.43633" upper="0.43633" velocity="48.8"/>
  </joint>
  <link name="Link_hip_l_roll">
    <inertial>
      <origin xyz="0.075725 -0.00093843 0.016591" rpy="0.0 0.0 0.0"/>
      <mass value="2.4334"/>
      <inertia ixx="0.0034464" ixy="9e-07" ixz="0.0001904" iyy="0.0042569" iyz="-6.6e-06" izz="0.0039063"/>
    </inertial>
    <visual>
      <origin xyz="0.0 0.0 0.0" rpy="0.0 0.0 0.0"/>
      <geometry>
        <mesh filename="package://openloong_description/meshes/Link_hip_l_roll.stl"/>
      </geometry>
      <material name="">
        <color rgba="0.89804 0.91765 0.92941 1.0"/>
      </material>
    </visual>
    <collision><origin xyz="0.0 0.0 0.0" rpy="0.0 0.0 0.0"/><geometry><mesh filename="file:///home/tim/github/ROS/robot_decompose/openloong_description/meshes/Link_hip_l_roll.stl_0.stl"/></geometry></collision><collision><origin xyz="0.0 0.0 0.0" rpy="0.0 0.0 0.0"/><geometry><mesh filename="file:///home/tim/github/ROS/robot_decompose/openloong_description/meshes/Link_hip_l_roll.stl_1.stl"/></geometry></collision><collision><origin xyz="0.0 0.0 0.0" rpy="0.0 0.0 0.0"/><geometry><mesh filename="file:///home/tim/github/ROS/robot_decompose/openloong_description/meshes/Link_hip_l_roll.stl_2.stl"/></geometry></collision><collision><origin xyz="0.0 0.0 0.0" rpy="0.0 0.0 0.0"/><geometry><mesh filename="file:///home/tim/github/ROS/robot_decompose/openloong_description/meshes/Link_hip_l_roll.stl_3.stl"/></geometry></collision><collision><origin xyz="0.0 0.0 0.0" rpy="0.0 0.0 0.0"/><geometry><mesh filename="file:///home/tim/github/ROS/robot_decompose/openloong_description/meshes/Link_hip_l_roll.stl_4.stl"/></geometry></collision><collision><origin xyz="0.0 0.0 0.0" rpy="0.0 0.0 0.0"/><geometry><mesh filename="file:///home/tim/github/ROS/robot_decompose/openloong_description/meshes/Link_hip_l_roll.stl_5.stl"/></geometry></collision><collision><origin xyz="0.0 0.0 0.0" rpy="0.0 0.0 0.0"/><geometry><mesh filename="file:///home/tim/github/ROS/robot_decompose/openloong_description/meshes/Link_hip_l_roll.stl_6.stl"/></geometry></collision></link>
  <joint name="J_hip_l_roll" type="revolute">
    <origin xyz="-0.0875 0.12 -0.069" rpy="0.0 0.0 0.0"/>
    <axis xyz="1.0 0.0 0.0"/>
    <parent link="Link_waist_yaw"/>
    <child link="Link_hip_l_roll"/>
    <limit effort="320.0" lower="-0.17453" upper="0.43633" velocity="20.94"/>
  </joint>
  <link name="Link_hip_l_yaw">
    <inertial>
      <origin xyz="-3.1716e-08 0.0071358 -0.10063" rpy="0.0 0.0 0.0"/>
      <mass value="3.4304"/>
      <inertia ixx="0.0077365" ixy="0.0" ixz="0.0" iyy="0.0080807" iyz="-0.0001167" izz="0.0066409"/>
    </inertial>
    <visual>
      <origin xyz="0.0 0.0 0.0" rpy="0.0 0.0 0.0"/>
      <geometry>
        <mesh filename="package://openloong_description/meshes/Link_hip_l_yaw.stl"/>
      </geometry>
      <material name="">
        <color rgba="0.89804 0.91765 0.92941 1.0"/>
      </material>
    </visual>
    <collision><origin xyz="0.0 0.0 0.0" rpy="0.0 0.0 0.0"/><geometry><mesh filename="file:///home/tim/github/ROS/robot_decompose/openloong_description/meshes/Link_hip_l_yaw.stl_0.stl"/></geometry></collision><collision><origin xyz="0.0 0.0 0.0" rpy="0.0 0.0 0.0"/><geometry><mesh filename="file:///home/tim/github/ROS/robot_decompose/openloong_description/meshes/Link_hip_l_yaw.stl_1.stl"/></geometry></collision><collision><origin xyz="0.0 0.0 0.0" rpy="0.0 0.0 0.0"/><geometry><mesh filename="file:///home/tim/github/ROS/robot_decompose/openloong_description/meshes/Link_hip_l_yaw.stl_2.stl"/></geometry></collision><collision><origin xyz="0.0 0.0 0.0" rpy="0.0 0.0 0.0"/><geometry><mesh filename="file:///home/tim/github/ROS/robot_decompose/openloong_description/meshes/Link_hip_l_yaw.stl_3.stl"/></geometry></collision><collision><origin xyz="0.0 0.0 0.0" rpy="0.0 0.0 0.0"/><geometry><mesh filename="file:///home/tim/github/ROS/robot_decompose/openloong_description/meshes/Link_hip_l_yaw.stl_4.stl"/></geometry></collision></link>
  <joint name="J_hip_l_yaw" type="revolute">
    <origin xyz="0.08225 -0.001 -0.01" rpy="0.0 0.0 0.0"/>
    <axis xyz="0.0 0.0 1.0"/>
    <parent link="Link_hip_l_roll"/>
    <child link="Link_hip_l_yaw"/>
    <limit effort="160.0" lower="-0.69813" upper="0.69813" velocity="19.63"/>
  </joint>
  <link name="Link_hip_l_pitch">
    <inertial>
      <origin xyz="0.0010856 0.05497 -0.14535" rpy="0.0 0.0 0.0"/>
      <mass value="5.2378"/>
      <inertia ixx="0.043457" ixy="-0.0002479" ixz="-0.0007626" iyy="0.037801" iyz="0.0007431" izz="0.015183"/>
    </inertial>
    <visual>
      <origin xyz="0.0 0.0 0.0" rpy="0.0 0.0 0.0"/>
      <geometry>
        <mesh filename="package://openloong_description/meshes/Link_hip_l_pitch.stl"/>
      </geometry>
      <material name="">
        <color rgba="0.69804 0.69804 0.69804 1.0"/>
      </material>
    </visual>
    <collision><origin xyz="0.0 0.0 0.0" rpy="0.0 0.0 0.0"/><geometry><mesh filename="file:///home/tim/github/ROS/robot_decompose/openloong_description/meshes/Link_hip_l_pitch.stl_0.stl"/></geometry></collision><collision><origin xyz="0.0 0.0 0.0" rpy="0.0 0.0 0.0"/><geometry><mesh filename="file:///home/tim/github/ROS/robot_decompose/openloong_description/meshes/Link_hip_l_pitch.stl_1.stl"/></geometry></collision></link>
  <joint name="J_hip_l_pitch" type="revolute">
    <origin xyz="0.0 -0.03675 -0.1055" rpy="0.0 0.0 0.0"/>
    <axis xyz="0.0 -1.0 0.0"/>
    <parent link="Link_hip_l_yaw"/>
    <child link="Link_hip_l_pitch"/>
    <limit effort="396.0" lower="-0.7854" upper="1.8326" velocity="19.16"/>
  </joint>
  <link name="Link_knee_l_pitch">
    <inertial>
      <origin xyz="-0.0096425 -2.8684e-06 -0.13601" rpy="0.0 0.0 0.0"/>
      <mass value="2.9775"/>
      <inertia ixx="0.023859" ixy="-6.76e-05" ixz="-0.0004656" iyy="0.024183" iyz="0.000548" izz="0.0023083"/>
    </inertial>
    <visual>
      <origin xyz="0.0 0.0 0.0" rpy="0.0 0.0 0.0"/>
      <geometry>
        <mesh filename="package://openloong_description/meshes/Link_knee_l_pitch.stl"/>
      </geometry>
      <material name="">
        <color rgba="0.66667 0.69804 0.76863 1.0"/>
      </material>
    </visual>
    <collision><origin xyz="0.0 0.0 0.0" rpy="0.0 0.0 0.0"/><geometry><mesh filename="file:///home/tim/github/ROS/robot_decompose/openloong_description/meshes/Link_knee_l_pitch.stl_0.stl"/></geometry></collision></link>
  <joint name="J_knee_l_pitch" type="revolute">
    <origin xyz="0.0 0.01125 -0.4" rpy="0.0 0.0 0.0"/>
    <axis xyz="0.0 -1.0 0.0"/>
    <parent link="Link_hip_l_pitch"/>
    <child link="Link_knee_l_pitch"/>
    <limit effort="396.0" lower="-2.35619" upper="0.08727" velocity="19.16"/>
  </joint>
  <link name="Link_ankle_l_pitch">
    <inertial>
      <origin xyz="-6.1835e-12 1.2655e-07 6.7022e-08" rpy="0.0 0.0 0.0"/>
      <mass value="0.10145"/>
      <inertia ixx="2.7175e-05" ixy="-1.0023e-14" ixz="-8.1752e-13" iyy="6.1118e-06" iyz="-2.6285e-11" izz="2.6565e-05"/>
    </inertial>
    <visual>
      <origin xyz="0.0 0.0 0.0" rpy="0.0 0.0 0.0"/>
      <geometry>
        <mesh filename="package://openloong_description/meshes/Link_ankle_l_pitch.stl"/>
      </geometry>
      <material name="">
        <color rgba="0.52941 0.54902 0.54902 1.0"/>
      </material>
    </visual>
    <collision><origin xyz="0.0 0.0 0.0" rpy="0.0 0.0 0.0"/><geometry><mesh filename="file:///home/tim/github/ROS/robot_decompose/openloong_description/meshes/Link_ankle_l_pitch.stl_0.stl"/></geometry></collision><collision><origin xyz="0.0 0.0 0.0" rpy="0.0 0.0 0.0"/><geometry><mesh filename="file:///home/tim/github/ROS/robot_decompose/openloong_description/meshes/Link_ankle_l_pitch.stl_1.stl"/></geometry></collision><collision><origin xyz="0.0 0.0 0.0" rpy="0.0 0.0 0.0"/><geometry><mesh filename="file:///home/tim/github/ROS/robot_decompose/openloong_description/meshes/Link_ankle_l_pitch.stl_2.stl"/></geometry></collision><collision><origin xyz="0.0 0.0 0.0" rpy="0.0 0.0 0.0"/><geometry><mesh filename="file:///home/tim/github/ROS/robot_decompose/openloong_description/meshes/Link_ankle_l_pitch.stl_3.stl"/></geometry></collision></link>
  <joint name="J_ankle_l_pitch" type="revolute">
    <origin xyz="0.0 0.0 -0.387" rpy="0.0 0.0 0.0"/>
    <axis xyz="0.0 -1.0 0.0"/>
    <parent link="Link_knee_l_pitch"/>
    <child link="Link_ankle_l_pitch"/>
    <limit effort="58.5" lower="-0.43644" upper="0.61087" velocity="48.8"/>
  </joint>
  <link name="Link_ankle_l_roll">
    <inertial>
      <origin xyz="0.041077 -2.9318e-08 -0.043909" rpy="0.0 0.0 0.0"/>
      <mass value="0.7522882"/>
      <inertia ixx="0.0004393" ixy="0.0" ixz="-0.000269" iyy="0.0036465" iyz="0.0" izz="0.0036369"/>
    </inertial>
    <visual>
      <origin xyz="0.0 0.0 0.0" rpy="0.0 0.0 0.0"/>
      <geometry>
        <mesh filename="package://openloong_description/meshes/Link_ankle_l_roll.stl"/>
      </geometry>
      <material name="">
        <color rgba="0.89804 0.91765 0.92941 1.0"/>
      </material>
    </visual>
    <collision><origin xyz="0.0 0.0 0.0" rpy="0.0 0.0 0.0"/><geometry><mesh filename="file:///home/tim/github/ROS/robot_decompose/openloong_description/meshes/Link_ankle_l_roll.stl_0.stl"/></geometry></collision><collision><origin xyz="0.0 0.0 0.0" rpy="0.0 0.0 0.0"/><geometry><mesh filename="file:///home/tim/github/ROS/robot_decompose/openloong_description/meshes/Link_ankle_l_roll.stl_1.stl"/></geometry></collision><collision><origin xyz="0.0 0.0 0.0" rpy="0.0 0.0 0.0"/><geometry><mesh filename="file:///home/tim/github/ROS/robot_decompose/openloong_description/meshes/Link_ankle_l_roll.stl_2.stl"/></geometry></collision><collision><origin xyz="0.0 0.0 0.0" rpy="0.0 0.0 0.0"/><geometry><mesh filename="file:///home/tim/github/ROS/robot_decompose/openloong_description/meshes/Link_ankle_l_roll.stl_3.stl"/></geometry></collision></link>
  <joint name="J_ankle_l_roll" type="revolute">
    <origin xyz="0.0 0.0 0.0" rpy="0.0 0.0 0.0"/>
    <axis xyz="1.0 0.0 0.0"/>
    <parent link="Link_ankle_l_pitch"/>
    <child link="Link_ankle_l_roll"/>
    <limit effort="58.5" lower="-0.43633" upper="0.43633" velocity="48.8"/>
  </joint>
</robot>
